We have new logging message:2024-11-09 11:03:12,014:ERROR:Exception
Traceback (most recent call last):
  File "D:\Tsibulko\C2121\c2121\python_s\p8_2.py", line 8, in <module>
    print(10/0)
ZeroDivisionError: division by zero
We have new logging message:2024-11-09 11:04:04,284:ERROR:Exception
Traceback (most recent call last):
  File "D:\Tsibulko\C2121\c2121\python_s\p8_2.py", line 8, in <module>
    print(10/0)
ZeroDivisionError: division by zero
